Traceback (most recent call last):
  File "/Users/winniecook/Documents/Updating_Projects/Script_Projects/forest-fire-analysis/scripts/03_statistical_modeling.py", line 60, in <module>
    main(input_file, output_file)
  File "/Users/winniecook/Documents/Updating_Projects/Script_Projects/forest-fire-analysis/scripts/03_statistical_modeling.py", line 39, in main
    X_train, X_test, y_train, y_test = prepare_data(df)
                                       ^^^^^^^^^^^^^^^^
  File "/Users/winniecook/Documents/Updating_Projects/Script_Projects/forest-fire-analysis/scripts/03_statistical_modeling.py", line 13, in prepare_data
    X = df[['temp', 'humid', 'wind', 'rain', 'FFMC', 'DMC', 'DC', 'ISI', 'BUI']]
        ~~^^^^^^^^^^^^^^^^^^^^^^^^^^^^^^^^^^^^^^^^^^^^^^^^^^^^^^^^^^^^^^^^^^^^^^
  File "/opt/anaconda3/lib/python3.12/site-packages/pandas/core/frame.py", line 4108, in __getitem__
    indexer = self.columns._get_indexer_strict(key, "columns")[1]
              ^^^^^^^^^^^^^^^^^^^^^^^^^^^^^^^^^^^^^^^^^^^^^^^^
  File "/opt/anaconda3/lib/python3.12/site-packages/pandas/core/indexes/base.py", line 6200, in _get_indexer_strict
    self._raise_if_missing(keyarr, indexer, axis_name)
  File "/opt/anaconda3/lib/python3.12/site-packages/pandas/core/indexes/base.py", line 6252, in _raise_if_missing
    raise KeyError(f"{not_found} not in index")
KeyError: "['humid', 'DMC', 'DC'] not in index"
